<?xml version="1.0"?>

<robot xmlns:xacro="http://wwww.ros.org/wiki/xacro" name="roverf">
<xacro:macro name="wheel_link" params="names">
<link name="${names}">
    <visual name="">
    <origin xyz="0.0 0.0 0.0" rpy="0.0 0.0 0.0"/>
        <geometry>
            <cylinder radius="${radius}" length="0.1"/>
        </geometry>
        <material name="black">
            <color rgba="0.0 0.0 0.0 1.0"/> 
        </material>
    </visual>
    <collision>
        <origin xyz="0.0 0.0 0.0" rpy="0.0 0.0 0.0"/>
        <geometry>
            <cylinder radius="${radius}" length="0.1"/>
        </geometry>
    </collision>
    <inertial>
        <mass value="0.5"/>
        <origin xyz="0.0 0.0 0.0" rpy="0.0 0.0 0.0"/>
        <inertia ixx="0.0" ixy="0.0" ixz="0.0" iyy="0.0" iyz="0.0" izz="0.0"/>
    </inertial>
</link>
</xacro:macro>

<macro name="wheel_joint" params="name1 child origin_xyz">
<joint name="${name1}" type="continuous">
    <parent link="base_link"/>
    <child link="${child}"/>
    <axis xyz="0 0 1"/>
    <origin xyz="${origin_xyz}" rpy="1.57 0 0"/>
</joint>
</xacro:macro>


</robot>